<?xml version='1.0' ?>
<sdf version='1.6'>
  <model name='amr'>
        <pose>0.0 0.0 -0.033 0 0 0</pose>
    	<link name='base_footprint' />
    		
      	<joint name='base_link_joint' type='fixed'>
      		<pose>0.235 0.025 0.033 0 0 1.5708</pose>
      		<parent>base_footprint</parent>
      		<child>base_link</child>
      	</joint>
    
    	<link name='base_link'>
      		<inertial>
      		        <pose>0 0 0 0 0 0</pose>
        		<mass>40.0302</mass>
        		<inertia>
          			<ixx>0.7463130412500001</ixx>
          			<ixy>0</ixy>
          			<ixz>0</ixz>
          			<iyy>0.7463130412500001</iyy>
          			<iyz>0</iyz>
          			<izz>0.105879879</izz>
        		</inertia>
        	</inertial>
        	
      		<collision name='base_link_collision'>
        		<pose relative_to='base_footprint' >0.235 0.025 0.033 0 0 1.5708</pose>
        		<geometry>
          			<mesh>
            				<uri>model://amr/meshes/ROBOTSEMNADA.dae</uri>
          			</mesh>
        		</geometry>
      		</collision>
      		<visual name='base_link_visual'>
        		<pose relative_to='base_footprint' >0.235 0.025 0.033 0 0 1.5708</pose>
        		<geometry>
          			<mesh>
            				<uri>model://amr/meshes/ROBOTSEMNADA.dae</uri>
          			</mesh>
        		</geometry>
        	</visual>
      </link>
      
      <joint name='torre_joint' type='fixed'>
      		<pose relative_to='base_link'>0.23 0 0.15 0 0 0</pose>
      		<parent>base_link</parent>
      		<child>torre_link</child>
      </joint>
      
      <link name='torre_link'>
      		<collision name='lidar_sensor_collision'>
          		<pose>0 0 0.285 0 0 1.5708</pose>
            		<geometry>
          			<mesh>
            				<uri>model://amr/meshes/torre001.dae</uri>
          			</mesh>
        		</geometry>
        	</collision>
      		<visual name='lidar_sensor_visual'>
        		<pose>0 0 0.285 0 0 1.5708</pose>
        		<geometry>    			
          			<mesh>
            				<uri>model://amr/meshes/torre001.dae</uri>
          			</mesh>
        		</geometry>
      		</visual>
      </link>
      
      <link name='realsense_link'>
      		<pose>0.23 0 0.15 0 0 0</pose>
      		<sensor name="cameracolor" type="camera">
        		<camera name="camera">
          			<horizontal_fov>1.57</horizontal_fov>
          			<image>
            				<width>1280</width>
            				<height>720</height>
            				<format>RGB_INT8</format>
          			</image>
          			<clip>
            				<near>0.1</near>
            				<far>100</far>
          			</clip>
          			<noise>
            				<type>gaussian</type>
            				<mean>0.0</mean>
            				<stddev>0.007</stddev>
          			</noise>
        		</camera>
        		<always_on>1</always_on>
        		<update_rate>30</update_rate>
        		<visualize>1</visualize>
     		</sensor>
      		<sensor name="cameradepth" type="depth">
        		<camera name="camera">
          			<horizontal_fov>1.57</horizontal_fov>
          			<image>
            				<width>1280</width>
            				<height>720</height>
          			</image>
          			<clip>
            				<near>0.1</near>
            				<far>100</far>
          			</clip>
          			<noise>
            				<type>gaussian</type>
            				<mean>0.0</mean>
            				<stddev>0.100</stddev>
          			</noise>
        		</camera>
        		<always_on>1</always_on>
        		<update_rate>30</update_rate>
        		<visualize>0</visualize>
     		 </sensor>
      		<sensor name="cameraired1" type="camera">
        <camera name="camera">
          <horizontal_fov>1.57</horizontal_fov>
          <image>
            <width>1280</width>
            <height>720</height>
            <format>L_INT8</format>
          </image>
          <clip>
            <near>0.1</near>
            <far>100</far>
          </clip>
          <noise>
            <type>gaussian</type>
            <mean>0.0</mean>
            <stddev>0.05</stddev>
          </noise>
        </camera>
        <always_on>1</always_on>
        <update_rate>1</update_rate>
        <visualize>0</visualize>
      </sensor>
      <sensor name="cameraired2" type="camera">
        <camera name="camera">
          <horizontal_fov>1.57</horizontal_fov>
          <image>
            <width>1280</width>
            <height>720</height>
            <format>L_INT8</format>
          </image>
          <clip>
            <near>0.1</near>
            <far>100</far>
          </clip>
          <noise>
            <type>gaussian</type>
            <mean>0.0</mean>
            <stddev>0.05</stddev>
          </noise>
        </camera>
        <always_on>1</always_on>
        <update_rate>1</update_rate>
        <visualize>0</visualize>
      </sensor>
      		
    		<collision name='camera_link_collision'>
       		<pose>0 0 0 0 -0 0</pose>
        		<geometry>
          			<sphere>
            				<radius>0.054</radius>
          			</sphere>
        		</geometry>
      		</collision> 
      		<visual name='camera_link_visual'>
        		<pose>0 0 0 1.57 0 1.57</pose>
        		<geometry>
          			<mesh>
            				<scale>1 1 1</scale>
            				<uri>model://amr/meshes/d435.dae</uri>
          			</mesh>
        		</geometry>
      		</visual>
      		<inertial>
        		<pose>0 0 0 0 0 0</pose>
        			<inertia>
          				<ixx>0.001</ixx>
          				<ixy>0.000</ixy>
          				<ixz>0.000</ixz>
          				<iyy>0.001</iyy>
          				<iyz>0.000</iyz>
          				<izz>0.001</izz>
        			</inertia>
        		<mass>0.564</mass>
      		</inertial>
      	</link>
    	
    	<joint name='camera_joint' type='fixed'>
      		<pose relative_to='base_link'>0.23 0 0.15 0 0 0</pose>
      		<parent>base_link</parent>
      		<child>realsense_link</child>
        </joint>
        <plugin name="camera" filename="librealsense_gazebo_plugin.so">
      	<prefix>camera</prefix>
      <depthUpdateRate>30.0</depthUpdateRate>
      <colorUpdateRate>30.0</colorUpdateRate>
      <infraredUpdateRate>1.0</infraredUpdateRate>
      <depthTopicName>aligned_depth_to_color/image_raw</depthTopicName>
      <depthCameraInfoTopicName>depth/camera_info</depthCameraInfoTopicName>
      <colorTopicName>color/image_raw</colorTopicName>
      <colorCameraInfoTopicName>color/camera_info</colorCameraInfoTopicName>
      <infrared1TopicName>infra1/image_raw</infrared1TopicName>
      <infrared1CameraInfoTopicName>infra1/camera_info</infrared1CameraInfoTopicName>
      <infrared2TopicName>infra2/image_raw</infrared2TopicName>
      <infrared2CameraInfoTopicName>infra2/camera_info</infrared2CameraInfoTopicName>
      <colorOpticalframeName>camera_rgb_optical_frame</colorOpticalframeName>
      <depthOpticalframeName>camera_depth_optical_frame</depthOpticalframeName>
      <infrared1OpticalframeName>camera_left_ir_optical_frame</infrared1OpticalframeName>
      <infrared2OpticalframeName>camera_right_ir_optical_frame</infrared2OpticalframeName>
      <rangeMinDepth>0.3</rangeMinDepth>
      <rangeMaxDepth>3.0</rangeMaxDepth>
      <pointCloud>true</pointCloud>
      <pointCloudTopicName>depth/color/points</pointCloudTopicName>
      <pointCloudCutoff>0.3</pointCloudCutoff>
    </plugin>
       
    	<joint name='lidar_joint' type='fixed'>
      		<pose>0.165 0 0.24 0 -0 0</pose>
      		<parent>base_link</parent>
      		<child>lidar_link</child>
    	</joint>
    
      	<link name='lidar_link'>
        	<inertial>
        <pose>-0.052 0 0.111 0 0 0</pose>
        <inertia>
          <ixx>0.001</ixx>
          <ixy>0.000</ixy>
          <ixz>0.000</ixz>
          <iyy>0.001</iyy>
          <iyz>0.000</iyz>
          <izz>0.001</izz>
        </inertia>
        <mass>0.114</mass>
      </inertial>
        	<collision name='lidar_sensor_collision'>
          		<pose>0.165 0 0.24 0 -0 0</pose>
          		<geometry>
            			<cylinder>
              				<radius>0.04</radius>
              				<length>0.02</length>
            			</cylinder>
          		</geometry>
        	</collision>
      		<visual name='lidar_sensor_visual'>
        		<pose>0.165 0 0.24 0 0 0</pose>
        		<geometry>
          			<cylinder>
            				<length>0.04</length>
            				<radius>0.02</radius>
          			</cylinder>
        		</geometry>
      		</visual>
      		<sensor name='amr_laserscan' type='ray'>
          		<always_on>1</always_on>
          		<visualize>1</visualize>
          		<pose>0.165 0 0.24 0 -0 0</pose>
          		<update_rate>10</update_rate>
          		<ray>
            			<scan>
              				<horizontal>
                				<samples>720</samples>
                				<resolution>0.5</resolution>
                				<min_angle>-2.194</min_angle>
                				<max_angle>2.194</max_angle>
              				</horizontal>
              				<vertical>
                				<samples>1</samples>
                				<min_angle>0</min_angle>
                				<max_angle>2</max_angle>
              				</vertical>
            			</scan>
            			<range>
              				<min>0.33</min>
              				<max>12.5</max>
              				<resolution>0.05</resolution>
            			</range>
            			<noise>
              				<type>gaussian</type>
              				<mean>0</mean>
              				<stddev>0.001</stddev>
            			</noise>
          		</ray>
          		<plugin name='base_scan' filename='libgazebo_ros_ray_sensor.so'>
            			<ros>
              				<remapping>~/out:=scan</remapping>
            			</ros>
            			<output_type>sensor_msgs/LaserScan</output_type>
            			<frame_name>base_scan</frame_name>
            			<base_frame_id>base_link</base_frame_id>
          		</plugin>
        	</sensor>
    </link>
  
    <!--isto está errado torna o robot instável-->  
    <joint name='pega_joint' type='fixed'>
    		<pose relative_to='base_footprint'>0 0 0.44 0 0 3.1415927</pose>
      		<parent>base_link</parent>
      		<child>pega_link</child>
    </joint>
  
    <link name='pega_link'>
      		<pose relative_to='base_footprint'>0 0 0.44 0 0 3.1415927</pose>
      <inertial>
        <pose>0 0 0 0 -0 0</pose>
        <mass>1.000</mass>
        <inertia>
        <ixx>0.00025349</ixx>
          <ixy>0</ixy>
          <ixz>0</ixz>
          <iyy>0.00025349</iyy>
          <iyz>0</iyz>
          <izz>0.000340312</izz>
          </inertia>
      </inertial>
      		<collision name='pega_link_collision'>
        		<pose>-.2 0 0 1.57 0 0</pose>
        		<geometry>
          			<mesh>
            				<uri>model://amr/meshes/pega001.dae</uri>
          			</mesh>
        		</geometry>
      		</collision>
      		<visual name='pega_link_visual'>
        		<pose>-.2 0 0 1.57 0 0</pose>
        		<geometry>
          			<mesh>
            				<scale>1 1 1</scale>
            				<uri>model://amr/meshes/pega001.dae</uri>
          			</mesh>
        		</geometry>
      		</visual>
    </link>

    <joint name='fcaster_joint' type='ball'>
    	<pose relative_to='base_footprint'>0.135 0 0.025 0 -0 0</pose>
    		<parent>base_link</parent>
      		<child>fcaster_link</child>
      		<axis>
        		<xyz>1 1 1</xyz>
        		<limit>
          			<lower>-1e+16</lower>
          			<upper>1e+16</upper>
          			<effort>1</effort>
          			<velocity>5</velocity>
        		</limit>
        		<dynamics>
          			<spring_reference>0</spring_reference>
          			<spring_stiffness>0</spring_stiffness>
        		</dynamics>
      		</axis>
    </joint>
    
    <link name='fcaster_link'>
      	<pose relative_to='base_footprint'>0.135 0 0.025 0 -0 0</pose>
      	<inertial>
        	<mass>1</mass>
        	<inertia>
          		<ixx>0.0025349</ixx>
          		<ixy>0</ixy>
          		<ixz>0</ixz>
          		<iyy>0.0025349</iyy>
          		<iyz>0</iyz>
          		<izz>0.00340312</izz>
        	</inertia>
      	</inertial>
      	<collision name='fcaster_link_collision'>
        	<pose>0 0 0.0 0 -0 0</pose>
        	<geometry>
          		<sphere>
            			<radius>0.025</radius>
          		</sphere>
        	</geometry>
      	</collision>
      	<visual name='fcaster_link_visual'>
        	<pose>0 0 0 0 0 0</pose>
        	<geometry>
          		<sphere>
            			<radius>0.025</radius>
          		</sphere>
        	</geometry>
      	</visual>
    </link>
    
    <joint name='rcaster_joint' type='ball'>
     	<pose relative_to='base_footprint'>-0.135 0 0.025 0 0 0</pose>
      	<parent>base_link</parent>
      	<child>rcaster_link</child>
      	<axis>
        	<xyz>1 1 1</xyz>
        	<limit>
          		<lower>-1e+16</lower>
          		<upper>1e+16</upper>
          		<effort>1</effort>
          		<velocity>5</velocity>
        	</limit>
        	<dynamics>
          		<spring_reference>0</spring_reference>
          		<spring_stiffness>0</spring_stiffness>
        	</dynamics>
      	</axis>
    </joint>
    
    <link name='rcaster_link'>
      	<pose relative_to='base_footprint'>-0.135 0 0.025 0 0 0</pose>
      	<inertial>
        	<mass>1</mass>
        	<inertia>
          		<ixx>0.0025349</ixx>
          		<ixy>0</ixy>
          		<ixz>0</ixz>
          		<iyy>0.0025349</iyy>
          		<iyz>0</iyz>
          		<izz>0.00340312</izz>
        	</inertia>
      	</inertial>
      	<collision name='rcaster_link_collision'>
        	<pose>0 0 0.0 0 -0 0</pose>
        	<geometry>
          		<sphere>
            			<radius>0.025</radius>
          		</sphere>
        	</geometry>
      	</collision>
      	<visual name='rcaster_link_visual'>
        	<pose>0 0 0.0 0 -0 0</pose>
        	<geometry>
          		<sphere>
            			<radius>0.025</radius>
          		</sphere>
        	</geometry>
      	</visual>
    </link>
    
    <joint name='lwheel_joint' type='revolute'>
      <pose relative_to='base_footprint'>0 0.1825 0.0825 -1.5708 0 0</pose>
      <parent>base_link</parent>
      <child>lwheel_link</child>
      <axis>
        <xyz>0 0 1</xyz>
        <limit>
          <lower>-1e+16</lower>
          <upper>1e+16</upper>
          <effort>1</effort>
          <velocity>5</velocity>
        </limit>
        <dynamics>
          <spring_reference>0</spring_reference>
          <spring_stiffness>0</spring_stiffness>
        </dynamics>
      </axis>
    </joint>
    
    <link name='lwheel_link'>
      <pose relative_to='base_footprint'>0 0.1825 0.0825 -1.5708 0 0</pose>
      <inertial>
        <pose>0 0 0 0 -0 0</pose>
        <mass>10.05</mass>
        <inertia>
          <ixx>0.00117223</ixx>
          <ixy>0</ixy>
          <ixz>0</ixz>
          <iyy>0.0117223</iyy>
          <iyz>0</iyz>
          <izz>0.00117223</izz>
        </inertia>
      </inertial>
      <collision name='lwheel_link_collision'>
        <pose>0 0 0 0 -0 0</pose>
        <geometry>
          <cylinder>
            <length>0.0435</length>
            <radius>0.0825</radius>
          </cylinder>
        </geometry>
      </collision>
      <visual name='lwheel_link_visual'>
        <pose>0 0 0 1.5708 -0 0</pose>
        <geometry>
          <mesh>
            <scale>1 1 1</scale>
            <uri>model://amr/meshes/amr_wheel.dae</uri>
          </mesh>
        </geometry>
      </visual>
    </link>
    
    <joint name='rwheel_joint' type='revolute'>
      <pose relative_to='base_footprint'>0 -0.1825 0.0825 1.5708 -0 0</pose>
      <parent>base_link</parent>
      <child>rwheel_link</child>
      <axis>
        <xyz>0 0 -1</xyz>
        <limit>
          <lower>-1e+16</lower>
          <upper>1e+16</upper>
          <effort>1</effort>
          <velocity>5</velocity>
        </limit>
        <dynamics>
          <spring_reference>0</spring_reference>
          <spring_stiffness>0</spring_stiffness>
        </dynamics>
      </axis>
    </joint>
    <link name='rwheel_link'>
      <pose relative_to='base_footprint'>0 -0.1825 0.0825 1.5708 -0 0</pose>
      <inertial>
        <pose>0 0 0 0 -0 0</pose>
        <mass>10.05</mass>
        <inertia>
          <ixx>0.00117223</ixx>
          <ixy>0</ixy>
          <ixz>0</ixz>
          <iyy>0.0117223</iyy>
          <iyz>0</iyz>
          <izz>0.00117223</izz>
        </inertia>
      </inertial>
      <collision name='rwheel_link_collision'>
        <pose>0 0 0 0 -0 0</pose>
        <geometry>
          <cylinder>
            <length>0.0435</length>
            <radius>0.0825</radius>
          </cylinder>
        </geometry>
      </collision>
      <visual name='rwheel_link_visual'>
        <pose>0 0 0 1.5708 -0 0</pose>
        <geometry>
          <mesh>
            <scale>1 1 1</scale>
            <uri>model://amr/meshes/amr_wheel.dae</uri>
          </mesh>
          <!--<sphere>
            <radius>0.055</radius>
          </sphere>-->
        </geometry>
      </visual>
    </link>
  
    <joint name='imu_joint' type='fixed'>
      <pose relative_to='base_footprint'>0.165 0 0.24 0 -0 0</pose>
      <parent>base_link</parent>
      <child>imu_link</child>
    </joint>
    
    <link name='imu_link'>
        <sensor name='tb3_imu' type='imu'>
          <always_on>1</always_on>
          <update_rate>20</update_rate>
          <imu>
            <angular_velocity>
              <x>
                <noise type='gaussian'>
                  <mean>0</mean>
                  <stddev>0.0002</stddev>
                </noise>
              </x>
              <y>
                <noise type='gaussian'>
                  <mean>0</mean>
                  <stddev>0.0002</stddev>
                </noise>
              </y>
              <z>
                <noise type='gaussian'>
                  <mean>0</mean>
                  <stddev>0.0002</stddev>
                </noise>
              </z>
            </angular_velocity>
            <linear_acceleration>
              <x>
                <noise type='gaussian'>
                  <mean>0</mean>
                  <stddev>0.017</stddev>
                </noise>
              </x>
              <y>
                <noise type='gaussian'>
                  <mean>0</mean>
                  <stddev>0.017</stddev>
                </noise>
              </y>
              <z>
                <noise type='gaussian'>
                  <mean>0</mean>
                  <stddev>0.017</stddev>
                </noise>
              </z>
            </linear_acceleration>
          </imu>
          <plugin name='amr_imu' filename='libgazebo_ros_imu_sensor.so'>
            <ros>
              <remapping>~/out:=imu</remapping>
            </ros>
          </plugin>
        </sensor>
        <self_collide>0</self_collide>
        <inertial>
          <pose>0 0 0 0 -0 0</pose>
          <inertia>
            <ixx>1</ixx>
            <ixy>0</ixy>
            <ixz>0</ixz>
            <iyy>1</iyy>
            <iyz>0</iyz>
            <izz>1</izz>
          </inertia>
          <mass>1</mass>
        </inertial>
        <enable_wind>0</enable_wind>
        <kinematic>0</kinematic>
      </link>
    
    <plugin name='amr_diff_drive' filename='libgazebo_ros_diff_drive.so'>
        <update_rate>10</update_rate>
        <left_joint>lwheel_joint</left_joint>
        <right_joint>rwheel_joint</right_joint>
        <wheel_separation>0.365</wheel_separation>
        <!--<odometrySource>world</odometrySource>  'encoder' instead of 'world' is also possible -->
        <!--<publishTf>1</publishTf>-->
        <wheel_diameter>0.23</wheel_diameter>
        <max_wheel_torque>20000</max_wheel_torque>
        <max_wheel_acceleration>1.0</max_wheel_acceleration>
        <command_topic>cmd_vel</command_topic>
        <odometry_topic>odometry</odometry_topic>
        <odometry_frame>odom</odometry_frame>
        <robot_base_frame>base_footprint</robot_base_frame>
        <!-- topic & remappings -->
        <ros>
   		<remapping>/cmd_vel:=diff_drive/cmd_vel</remapping>
  	</ros>
  	<publish_odom>1</publish_odom>
        <publish_odom_tf>1</publish_odom_tf>
        <publish_wheel_tf>0</publish_wheel_tf>
    </plugin>
    <plugin name='amr_joint_state' filename='libgazebo_ros_joint_state_publisher.so'>
        <ros>
          <remapping>~/out:=joint_states</remapping>
        </ros>
        <update_rate>30</update_rate>
        <joint_name>lwheel_joint</joint_name>
        <joint_name>rwheel_joint</joint_name>
      </plugin>
  </model>
</sdf>
