<?xml version="1.0" ?>
<!-- =================================================================================== -->
<!-- |    This document was autogenerated by xacro from jetracer.xacro                 | -->
<!-- |    EDITING THIS FILE BY HAND IS NOT RECOMMENDED                                 | -->
<!-- =================================================================================== -->
<robot name="jetracer">
  <material name="black">
    <color rgba="0 0 0 1"/>
  </material>
  <link name="base_footprint"/>
  <joint name="base_to_base" type="fixed">
    <parent link="base_footprint"/>
    <child link="base_link"/>
    <origin rpy="0 0 0" xyz="0 0 0"/>
  </joint>
  <link name="base_link">
    <visual>
      <orgin rpy="0 0 0" xyz="0 0 0"/>
      <geometry>
        <box size="1 2 0.3"/>
      </geometry>
    </visual>
  </link>
  <!--Front left wheel-->
  <joint name="fl_holder_joint" type="revolute">
    <axis xyz="0 0 1"/>
    <limit effort="1000.0" lower="-0.4" upper="0.4" velocity="0.5"/>
    <origin rpy="0 0 0" xyz="-0.5 0.8 0"/>
    <parent link="base_link"/>
    <child link="fl_wheel_link"/>
  </joint>
  <link name="fl_wheel_link">
    <visual>
      <orgin rpy="0 0 0" xyz="-0.7 0.8 0"/>
      <geometry>
        <box size="0 0 0"/>
      </geometry>
    </visual>
  </link>
  <joint name="fl_wheel_joint" type="continuous">
    <axis xyz="0 0 1"/>
    <origin rpy="0 1.57 0" xyz="-0.2 0 0"/>
    <parent link="fl_wheel_link"/>
    <child link="fl_wheel"/>
  </joint>
  <link name="fl_wheel">
    <visual>
      <orgin rpy="0 0 0" xyz="-0.7 0.8 0"/>
      <geometry>
        <cylinder length="0.2" radius="0.4"/>
      </geometry>
      <material name="black"/>
    </visual>
  </link>
  <!--Front right wheel-->
  <joint name="fr_holder_joint" type="revolute">
    <axis xyz="0 0 1"/>
    <limit effort="1000.0" lower="-0.4" upper="0.4" velocity="0.5"/>
    <origin rpy="0 0 0" xyz="0.5 0.8 0"/>
    <parent link="base_link"/>
    <child link="fr_wheel_link"/>
  </joint>
  <link name="fr_wheel_link">
    <visual>
      <orgin rpy="0 0 0" xyz="0.7 0.8 0"/>
      <geometry>
        <box size="0 0 0"/>
      </geometry>
    </visual>
  </link>
  <joint name="fr_wheel_joint" type="continuous">
    <axis xyz="0 0 1"/>
    <origin rpy="0 1.57 0" xyz="0.2 0 0"/>
    <parent link="fr_wheel_link"/>
    <child link="fr_wheel"/>
  </joint>
  <link name="fr_wheel">
    <visual>
      <orgin rpy="0 0 0" xyz="0.7 0.8 0"/>
      <geometry>
        <cylinder length="0.2" radius="0.4"/>
      </geometry>
      <material name="black"/>
    </visual>
  </link>
  <!--Rear left wheel-->
  <joint name="rl_wheel_joint" type="continuous">
    <axis xyz="0 0 1"/>
    <origin rpy="0 1.57 0" xyz="-0.7 -0.8 0"/>
    <parent link="base_link"/>
    <child link="rl_wheel"/>
  </joint>
  <link name="rl_wheel">
    <visual>
      <orgin rpy="0 0 0" xyz="-0.7 -0.8 0"/>
      <geometry>
        <cylinder length="0.2" radius="0.4"/>
      </geometry>
      <material name="black"/>
    </visual>
  </link>
  <!--Rear right wheel-->
  <joint name="rr_wheel_joint" type="continuous">
    <axis xyz="0 0 1"/>
    <origin rpy="0 1.57 0" xyz="0.7 -0.8 0"/>
    <parent link="base_link"/>
    <child link="rr_wheel"/>
  </joint>
  <link name="base_scan">
    <visual>
      <geometry>
        <cylinder length="0.04" radius="0.02"/>
      </geometry>
      <origin rpy="0 0 0" xyz="0 0 0.0"/>
      <material name="black">
        <color rgba="0 0 0 1"/>
      </material>
    </visual>
  </link>
  <joint name="base_to_scanner" type="fixed">
    <parent link="base_link"/>
    <child link="base_scan"/>
    <origin rpy="0 0 0" xyz="0.165 0 0.24"/>
  </joint>
  <link name="rr_wheel">
    <visual>
      <orgin rpy="0 0 0" xyz="0 0 0"/>
      <geometry>
        <cylinder length="0.2" radius="0.4"/>
      </geometry>
      <material name="black"/>
    </visual>
  </link>
</robot>
