<?xml version="1.0" ?>
<!-- =================================================================================== -->
<!-- |    This document was autogenerated by xacro from two_wheeled_robot_nav2.urdf.xacro | -->
<!-- |    EDITING THIS FILE BY HAND IS NOT RECOMMENDED                                 | -->
<!-- =================================================================================== -->
<robot name="twr">
  <!-- ********************** ROBOT BASE *********************************  -->
  <link name="base_link">
    <visual>
      <origin rpy="1.5707963267949 0 3.141592654" xyz="0 0 -0.05"/>
      <geometry>
        <mesh filename="file:///home/jpalves/dev_ws/install/two_wheeled_robot/share/two_wheeled_robot/meshes/robot_base.stl"/>
      </geometry>
      <material name="Red">
        <color rgba="1.0 0.0 0.0 1.0"/>
      </material>
    </visual>
    <collision>
      <geometry>
        <box size="0.7 0.39 0.2"/>
      </geometry>
    </collision>
    <inertial>
      <origin rpy="1.5707963267948966 0 1.5707963267948966" xyz="0 0 0"/>
      <mass value="15.0"/>
      <inertia ixx="0.6624999999999999" ixy="0.0" ixz="0.0" iyy="0.8026249999999999" iyz="0.0" izz="0.24012500000000003"/>
    </inertial>
  </link>
  <gazebo reference="base_link">
    <material>Gazebo/Red</material>
  </gazebo>
  <!-- ****************** ROBOT BASE FOOTPRINT ***************************  -->
  <!-- Define the center of the main robot chassis projected on the ground -->
  <link name="base_footprint">
    <!--<xacro:box_inertia m="0" w="0" d="0" h="0"/>-->
  </link>
  <!-- The base footprint of the robot is located underneath the chassis -->
  <joint name="base_joint" type="fixed">
    <parent link="base_footprint"/>
    <child link="base_link"/>
    <origin rpy="0 0 0" xyz="0.0 0.0 -0.19"/>
  </joint>
  <link name="drivewhl_l_link">
    <visual>
      <origin rpy="1.5707963267948966 0 0" xyz="0 0 0"/>
      <geometry>
        <cylinder length="0.06" radius="0.14"/>
      </geometry>
      <material name="Gray">
        <color rgba="0.5 0.5 0.5 1.0"/>
      </material>
    </visual>
    <collision>
      <origin rpy="1.5707963267948966 0 0" xyz="0 0 0"/>
      <geometry>
        <cylinder length="0.06" radius="0.14"/>
      </geometry>
    </collision>
    <inertial>
      <origin rpy="1.5707963267948966 0 0" xyz="0 0 0"/>
      <mass value="0.5"/>
      <inertia ixx="0.0026000000000000003" ixy="0" ixz="0" iyy="0.0026000000000000003" iyz="0" izz="0.004900000000000001"/>
    </inertial>
  </link>
  <!-- Connect the wheels to the base_link at the appropriate location, and 
         define a continuous joint to allow the wheels to freely rotate about
         an axis -->
  <joint name="drivewhl_l_joint" type="continuous">
    <parent link="base_link"/>
    <child link="drivewhl_l_link"/>
    <origin rpy="0 0 0" xyz="-0.221 0.23 -0.05"/>
    <axis xyz="0 1 0"/>
  </joint>
  <link name="drivewhl_r_link">
    <visual>
      <origin rpy="1.5707963267948966 0 0" xyz="0 0 0"/>
      <geometry>
        <cylinder length="0.06" radius="0.14"/>
      </geometry>
      <material name="Gray">
        <color rgba="0.5 0.5 0.5 1.0"/>
      </material>
    </visual>
    <collision>
      <origin rpy="1.5707963267948966 0 0" xyz="0 0 0"/>
      <geometry>
        <cylinder length="0.06" radius="0.14"/>
      </geometry>
    </collision>
    <inertial>
      <origin rpy="1.5707963267948966 0 0" xyz="0 0 0"/>
      <mass value="0.5"/>
      <inertia ixx="0.0026000000000000003" ixy="0" ixz="0" iyy="0.0026000000000000003" iyz="0" izz="0.004900000000000001"/>
    </inertial>
  </link>
  <!-- Connect the wheels to the base_link at the appropriate location, and 
         define a continuous joint to allow the wheels to freely rotate about
         an axis -->
  <joint name="drivewhl_r_joint" type="continuous">
    <parent link="base_link"/>
    <child link="drivewhl_r_link"/>
    <origin rpy="0 0 0" xyz="-0.221 -0.23 -0.05"/>
    <axis xyz="0 1 0"/>
  </joint>
  <!-- *********************** CASTER WHEEL ******************************  -->
  <!-- We add a caster wheel. It will be modeled as sphere.
       We define the wheel’s geometry, material and the joint to connect it to 
       base_link at the appropriate location. -->
  <link name="front_caster">
    <visual>
      <geometry>
        <sphere radius="0.09"/>
      </geometry>
      <material name="Cyan">
        <color rgba="0 1.0 1.0 1.0"/>
      </material>
    </visual>
    <collision>
      <origin rpy="0 0 0" xyz="0 0 0"/>
      <geometry>
        <sphere radius="0.09"/>
      </geometry>
    </collision>
    <inertial>
      <mass value="0.5"/>
      <inertia ixx="0.00162" ixy="0.0" ixz="0.0" iyy="0.00162" iyz="0.0" izz="0.00162"/>
    </inertial>
  </link>
  <gazebo reference="front_caster">
    <mu1>0.01</mu1>
    <mu2>0.01</mu2>
    <material>Gazebo/White</material>
  </gazebo>
  <joint name="caster_joint" type="fixed">
    <parent link="base_link"/>
    <child link="front_caster"/>
    <origin rpy="0 0 0" xyz="0.217 0.0 -0.1"/>
  </joint>
  <!-- *********************** IMU SETUP *********************************  -->
  <!-- Each sensor must be attached to a link.                              -->
  <link name="imu_link">
    <visual>
      <geometry>
        <box size="0.1 0.1 0.1"/>
      </geometry>
    </visual>
    <collision>
      <geometry>
        <box size="0.1 0.1 0.1"/>
      </geometry>
    </collision>
    <inertial>
      <origin rpy="1.5707963267948966 0 1.5707963267948966" xyz="0 0 0"/>
      <mass value="0.1"/>
      <inertia ixx="0.0001666666666666667" ixy="0.0" ixz="0.0" iyy="0.0001666666666666667" iyz="0.0" izz="0.0001666666666666667"/>
    </inertial>
  </link>
  <joint name="imu_joint" type="fixed">
    <parent link="base_link"/>
    <child link="imu_link"/>
    <origin xyz="0 0 0.01"/>
  </joint>
  <gazebo reference="imu_link">
    <gravity>true</gravity>
    <sensor name="twr_imu" type="imu">
      <always_on>true</always_on>
      <update_rate>100</update_rate>
      <visualize>true</visualize>
      <imu>
        <orientation>
          <x>
            <noise type="gaussian">
              <mean>0.0</mean>
              <stddev>2e-3</stddev>
            </noise>
          </x>
          <y>
            <noise type="gaussian">
              <mean>0.0</mean>
              <stddev>2e-3</stddev>
            </noise>
          </y>
          <z>
            <noise type="gaussian">
              <mean>0.0</mean>
              <stddev>2e-3</stddev>
            </noise>
          </z>
        </orientation>
        <angular_velocity>
          <x>
            <noise type="gaussian">
              <mean>0.0</mean>
              <stddev>2e-4</stddev>
            </noise>
          </x>
          <y>
            <noise type="gaussian">
              <mean>0.0</mean>
              <stddev>2e-4</stddev>
            </noise>
          </y>
          <z>
            <noise type="gaussian">
              <mean>0.0</mean>
              <stddev>2e-4</stddev>
            </noise>
          </z>
        </angular_velocity>
        <linear_acceleration>
          <x>
            <noise type="gaussian">
              <mean>0.0</mean>
              <stddev>1.7e-2</stddev>
            </noise>
          </x>
          <y>
            <noise type="gaussian">
              <mean>0.0</mean>
              <stddev>1.7e-2</stddev>
            </noise>
          </y>
          <z>
            <noise type="gaussian">
              <mean>0.0</mean>
              <stddev>1.7e-2</stddev>
            </noise>
          </z>
        </linear_acceleration>
      </imu>
      <plugin filename="libgazebo_ros_imu_sensor.so" name="two_wheeled_robot_imu">
        <initial_orientation_as_reference>false</initial_orientation_as_reference>
        <frame_name>imu_link</frame_name>
        <ros>
          <namespace>/imu</namespace>
          <remapping>~/out:=data</remapping>
        </ros>
      </plugin>
    </sensor>
  </gazebo>
  <!-- *********************** LIDAR SETUP **********************************  -->
  <link name="base_scan">
    <inertial>
      <origin rpy="0 0 0" xyz="0 0 0"/>
      <mass value="0.125"/>
      <inertia ixx="0.001" ixy="0" ixz="0" iyy="0.001" iyz="0" izz="0.001"/>
    </inertial>
    <collision>
      <origin rpy="0 0 0" xyz="0 0 0"/>
      <geometry>
        <cylinder length="0.75" radius="0.0508"/>
      </geometry>
    </collision>
    <visual>
      <origin rpy="0 0 0" xyz="0 0 0"/>
      <geometry>
        <cylinder length="0.75" radius="0.0508"/>
      </geometry>
    </visual>
  </link>
  <joint name="lidar_joint" type="fixed">
    <parent link="base_link"/>
    <child link="base_scan"/>
    <origin rpy="0 0 0" xyz="0.215 0.0 0.30"/>
  </joint>
  <gazebo reference="base_scan">
    <sensor name="lidar" type="ray">
      <always_on>true</always_on>
      <visualize>true</visualize>
      <update_rate>5</update_rate>
      <ray>
        <scan>
          <horizontal>
            <samples>120</samples>
            <resolution>1.000000</resolution>
            <min_angle>-3.14159</min_angle>
            <max_angle>3.14159</max_angle>
          </horizontal>
        </scan>
        <range>
          <min>0.3</min>
          <max>15.0</max>
          <resolution>0.015</resolution>
        </range>
        <noise>
          <type>gaussian</type>
          <mean>0.0</mean>
          <stddev>0.01</stddev>
        </noise>
      </ray>
      <plugin filename="libgazebo_ros_ray_sensor.so" name="scan">
        <ros>
          <remapping>~/out:=scan</remapping>
        </ros>
        <output_type>sensor_msgs/LaserScan</output_type>
        <frame_name>base_scan</frame_name>
      </plugin>
    </sensor>
  </gazebo>
  <gazebo reference="base_scan">
    <mu1>0.01</mu1>
    <mu2>0.01</mu2>
    <material>Gazebo/Black</material>
  </gazebo>
  <!-- *********************** WHEEL ODOMETRY ***************************    -->
  <gazebo>
    <plugin filename="libgazebo_ros_diff_drive.so" name="two_wheeled_robot_diff_drive">
      <update_rate>30</update_rate>
      <!-- wheels -->
      <left_joint>drivewhl_l_joint</left_joint>
      <right_joint>drivewhl_r_joint</right_joint>
      <!-- kinematics -->
      <wheel_separation>0.52</wheel_separation>
      <wheel_diameter>0.28</wheel_diameter>
      <!-- limits -->
      <max_wheel_torque>20</max_wheel_torque>
      <max_wheel_acceleration>1.0</max_wheel_acceleration>
      <!-- Receive velocity commands on this ROS topic -->
      <command_topic>cmd_vel</command_topic>
      <!-- output -->
      <!-- When false, publish no wheel odometry data to a ROS topic -->
      <publish_odom>true</publish_odom>
      <!-- When true, publish coordinate transform from odom to base_footprint -->
      <!-- I usually use the robot_localization package to publish this transform -->
      <publish_odom_tf>true</publish_odom_tf>
      <!-- When true, publish coordinate transform from base_link to the wheels -->
      <!-- The robot_state_publisher package is often used to publish this transform -->
      <publish_wheel_tf>true</publish_wheel_tf>
      <odometry_topic>odom</odometry_topic>
      <odometry_frame>odom</odometry_frame>
      <robot_base_frame>base_link</robot_base_frame>
      <odometry_source>1</odometry_source>
      <!--ros>
        <remapping>odom:=wheel/odometry</remapping>
      </ros-->
      <ros>
      <remapping>cmd_vel:=diff_drive/cmd_vel</remapping>
    </ros>
    </plugin>
  </gazebo>
</robot>
