<?xml version="1.0" ?>
<!-- =================================================================================== -->
<!-- |    This document was autogenerated by xacro from verde.xacro                    | -->
<!-- |    EDITING THIS FILE BY HAND IS NOT RECOMMENDED                                 | -->
<!-- =================================================================================== -->
<robot name="verde">
  <material name="black">
    <color rgba="0 0 0 1"/>
  </material>
  <link name="base_footprint"/>
  <joint name="base_to_base" type="fixed">
    <parent link="base_footprint"/>
    <child link="base_link"/>
    <origin rpy="0 0 0" xyz="0 0 0"/>
  </joint>
  <link name="base_link">
    <visual>
      <orgin rpy="0 0 0" xyz="0 0 0"/>
      <geometry>
        <box size="0.21 0.135 0.035"/>
        <!-- ver medidas -->
      </geometry>
    </visual>
    <collision>
      <orgin rpy="0 0 0" xyz="0 0 0"/>
      <geometry>
        <box size="0.21 0.135 0.035"/>
      </geometry>
    </collision>
  </link>
  <!--Front left wheel-->
  <joint name="fl_holder_joint" type="revolute">
    <axis xyz="0 0 1"/>
    <limit effort="1000.0" lower="-0.4" upper="0.4" velocity="0.5"/>
    <origin rpy="0 0 0" xyz="0.07 -0.037 0.0175"/>
    <parent link="base_link"/>
    <child link="fl_wheel_link"/>
  </joint>
  <link name="fl_wheel_link">
    <visual>
      <orgin rpy="0 0 0" xyz="0.07 -0.037 0.0175"/>
      <geometry>
        <box size="0 0 0"/>
      </geometry>
    </visual>
  </link>
  <joint name="fl_wheel_joint" type="continuous">
    <axis xyz="0 0 1"/>
    <origin rpy="0 1.57 0" xyz="-0.2 0 0"/>
    <parent link="fl_wheel_link"/>
    <child link="fl_wheel"/>
  </joint>
  <link name="fl_wheel">
    <visual>
      <orgin rpy="0 0 0" xyz="0.07 -0.037 0.0175"/>
      <geometry>
        <cylinder length="0.023" radius="0.034"/>
      </geometry>
      <material name="black"/>
    </visual>
    <collision>
      <orgin rpy="0 0 0" xyz="0.07 -0.037 0.0175"/>
      <geometry>
        <cylinder length="0.023" radius="0.034"/>
      </geometry>
    </collision>
  </link>
  <!--Front right wheel-->
  <joint name="fr_holder_joint" type="revolute">
    <axis xyz="0 0 1"/>
    <limit effort="1000.0" lower="-0.4" upper="0.4" velocity="0.5"/>
    <origin rpy="0 0 0" xyz="0.07 0.037 0.0175"/>
    <parent link="base_link"/>
    <child link="fr_wheel_link"/>
  </joint>
  <link name="fr_wheel_link">
    <visual>
      <orgin rpy="0 0 0" xyz="0.07 0.037 0.0175"/>
      <geometry>
        <box size="0 0 0"/>
      </geometry>
    </visual>
  </link>
  <joint name="fr_wheel_joint" type="continuous">
    <axis xyz="0 0 1"/>
    <origin rpy="0 1.57 0" xyz="0.07 0.037 0.0175"/>
    <parent link="fr_wheel_link"/>
    <child link="fr_wheel"/>
  </joint>
  <link name="fr_wheel">
    <visual>
      <orgin rpy="0 0 0" xyz="0.07 0.037 0.0175"/>
      <geometry>
        <cylinder length="0.023" radius="0.034"/>
      </geometry>
      <material name="black"/>
    </visual>
    <collision>
      <orgin rpy="0 0 0" xyz="0.07 0.037 0.0175"/>
      <geometry>
        <cylinder length="0.023" radius="0.034"/>
      </geometry>
    </collision>
  </link>
  <!-- falta o caster isto é tudo para ver e medir-->
  <link name="fcaster_link">
    <visual>
      <geometry>
        <sphere radius="0.025"/>
      </geometry>
      <origin rpy="0 0 0" xyz="0 0 0"/>
      <material name="white">
        <color rgba="1 1 1 1"/>
      </material>
    </visual>
    <collision>
      <origin rpy="0 0 0" xyz="0 0 0"/>
      <geometry>
        <sphere radius="0.025"/>
      </geometry>
    </collision>
    <inertial>
      <origin rpy="0 0 0" xyz="0 0 0"/>
      <mass value="1"/>
      <inertia ixx="0.0025348958333333334" ixy="0" ixz="0" iyy="0.0025348958333333334" iyz="0" izz="0.0034031250000000003"/>
    </inertial>
  </link>
  <joint name="fcaster_joint" type="revolute">
    <parent link="base_link"/>
    <child link="fcaster_link"/>
    <origin rpy="0 0 0" xyz="-0.084 0 0"/>
    <limit effort="1" lower="0" upper="0" velocity="5.0"/>
  </joint>
  <link name="base_scan">
    <visual>
      <geometry>
        <cylinder length="0.0" radius="0.0"/>
      </geometry>
      <origin rpy="0 0 3.1415927" xyz="-0.048 0 0.0"/>
      <material name="black">
        <color rgba="0 0 0 1"/>
      </material>
    </visual>
  </link>
  <joint name="base_to_scanner" type="fixed">
    <parent link="base_link"/>
    <child link="base_scan"/>
    <origin rpy="0 0 0" xyz="-0.048 0 0.157"/>
  </joint>
  <link name="imu_link"/>
  <joint name="imu_joint" type="fixed">
    <parent link="base_link"/>
    <child link="imu_link"/>
    <origin rpy="0 0 0" xyz="0 0 0"/>
  </joint>
  <!--************* ROBOT'S CAMERA **************-->
  <link name="camera_link">
    <visual>
      <geometry>
        <cylinder length="0.001" radius="0.001"/>
      </geometry>
      <origin rpy="0 0 1.57" xyz="0 0 0"/>
      <material name="black">
        <color rgba="0 0 0 1"/>
      </material>
    </visual>
  </link>
  <joint name="camera_joint" type="fixed">
    <parent link="base_link"/>
    <child link="camera_link"/>
    <origin rpy="0 0 0" xyz="0.0 0.0 0.04"/>
  </joint>
</robot>
